<mujoco model="boxhead">
  <compiler boundmass="1e-05" boundinertia="1e-11" coordinate="local" angle="radian" eulerseq="xyz"/>
  <option timestep="0.005" cone="elliptic" noslip_iterations="5" noslip_tolerance="0.0"/>
  <size njmax="800" nconmax="800"/>
  <visual>
    <headlight ambient="0.40000000000000002 0.40000000000000002 0.40000000000000002" diffuse="0.80000000000000004 0.80000000000000004 0.80000000000000004" specular="0.10000000000000001 0.10000000000000001 0.10000000000000001"/>
    <map znear="0.0005"/>
    <scale forcewidth="0.01" contactwidth="0.06" contactheight="0.01" jointwidth="0.01" framelength="0.3" framewidth="0.01"/>
  </visual>
  <default>
    <default class="/">
      <mesh scale="0.01 0.01 0.01"/>
      <geom contype="1" conaffinity="1" condim="4" friction="0.5 0.02 0.02"/>
      <default class="root">
        <joint pos="0 0 0" limited="false" stiffness="0.0" armature="0.0" damping="0.0"/>
      </default>
    </default>
  </default>
  <asset>
    <!-- <texture name="head_texture" type="2d" file="0ec62e5b91e60ed44b61fabab6ca0e7576caa548.png"/> -->
    <material name="head_material" class="/" texture="ball_body"/>
    <texture name="ball_body" type="cube" builtin="checker" rgb1="0.10000000000000001 0.10000000000000001 0.80000000000000004" rgb2="0.80000000000000004 0.80000000000000004 0.80000000000000004" width="100" height="100"/>
    <material name="ball_body" class="/" texture="ball_body"/>
  </asset>
  <worldbody>
    <body name="head_body" pos="0 0 1" quat="1 0 0 -1">
      <camera name="float_far" class="/" fovy="90.0" pos="-4 0 2" xyaxes="0 -1 0 0.5 0 1"/>
      <body name="egocentric_camera" pos="0.1 0 0.2" xyaxes="0 -1 0 0.0995 0 0.995">
        <inertial pos="0 0 0" mass="1.0" diaginertia="1 1 1"/>
        <geom name="eye_l" class="/" type="cylinder" contype="0" conaffinity="0" size="0.06 0.05" rgba="0.1 0.1 0.8 1" mass="0.0" pos="-0.14 -0.2 -0.171"/>
        <geom name="eye_r" class="/" type="cylinder" contype="0" conaffinity="0" size="0.06 0.05" rgba="0.1 0.1 0.8 1" mass="0.0" pos="0.14 -0.2 -0.171"/>
        <camera name="egocentric" class="/" fovy="80.0"/>
      </body>
      <camera name="tracking" class="/" mode="trackcom" pos="1.5 1.5 0.69999999999999996" xyaxes="-1 1 0 -1 -1 4"/>
      <joint name="steer" class="root" type="hinge" axis="0 0 -1" damping="4.0"/>
      <geom name="top_down_cam_box" class="/" type="box" contype="0" conaffinity="0" group="5" size="1 1 0.10000000000000001" material="head_material" mass="0.0" pos="0 0 2"/>
      <geom name="head" class="/" type="box" contype="1" conaffinity="1" size="0.20000000000000001 0.20000000000000001 0.10000000000000001" material="head_material" mass="20.0" pos="0 0 0"/>
      <site name="torso_site" class="/" group="4" rgba="1 0 0 1" size="0.050000000000000003" pos="0 0 0"/>
      <body name="torso" pos="0 0 0.050000000000000003">
        <joint name="kick" class="/" type="slide" axis="0 0 -1" limited="true" solimplimit="0.94999999999999996 0.98999999999999999 0.001" stiffness="0.0" range="0 0.40000000000000002" springref="-0.4" damping="100.0"/>
        <geom name="arm_l" class="/" type="capsule" size="0.10000000000000001" rgba="0.10000000000000001 0.10000000000000001 0.80000000000000004 1" density="10.0" fromto="0 0.34999999999999998 -0.69999999999999996 0.029999999999999999 0.80000000000000004 -0.69999999999999996"/>
        <geom name="arm_r" class="/" type="capsule" size="0.10000000000000001" rgba="0.10000000000000001 0.10000000000000001 0.80000000000000004 1" density="10.0" fromto="0 -0.34999999999999998 -0.69999999999999996 0.029999999999999999 -0.80000000000000004 -0.69999999999999996"/>
        <body name="ball" pos="0 0 -0.69999999999999996">
          <joint name="roll" class="/" type="hinge" axis="0 1 0" damping="2.0"/>
          <geom name="shell" class="/" type="sphere" condim="4" size="0.34999999999999998" material="ball_body" friction="0.5 0.02 0.02" density="100.0"/>
        </body>
      </body>
    </body>
  </worldbody>
  <actuator>
    <general name="roll" class="/" ctrllimited="true" ctrlrange="-1 1" gear="-60" joint="roll" biastype="affine" biasprm="0"/>
    <motor name="steer" class="/" ctrllimited="true" ctrlrange="-1 1" gear="55" joint="steer"/>
    <!-- <general name="kick" class="/" ctrllimited="true" ctrlrange="-1 1" gear="1200" joint="kick" biastype="affine" biasprm="0"/> -->
  </actuator>
  <sensor>
    <velocimeter name="sensor_torso_vel" site="torso_site"/>
    <gyro name="sensor_torso_gyro" site="torso_site"/>
    <accelerometer name="sensor_torso_accel" site="torso_site"/>
  </sensor>
</mujoco>
